I'm sorry, but an uncaught exception occurred.

While running game code:
Exception: Line with id part_3_murder_memory_f5ff85b5_2 appeared twice, at game/murder.rpy:88 and game/part_3.rpy:68.

-- Full Traceback ------------------------------------------------------------

Full traceback:
  File "C:\Users\Quirk\Documents\RenPy-Competition\renpy\bootstrap.py", line 277, in bootstrap
    renpy.main.main()
  File "C:\Users\Quirk\Documents\RenPy-Competition\renpy\main.py", line 490, in main
    renpy.game.script.load_script() # sets renpy.game.script.
  File "C:\Users\Quirk\Documents\RenPy-Competition\renpy\script.py", line 297, in load_script
    self.load_appropriate_file(".rpyc", ".rpy", dir, fn, initcode)
  File "C:\Users\Quirk\Documents\RenPy-Competition\renpy\script.py", line 809, in load_appropriate_file
    self.finish_load(stmts, initcode, filename=lastfn) # type: ignore
  File "C:\Users\Quirk\Documents\RenPy-Competition\renpy\script.py", line 427, in finish_load
    self.translator.take_translates(all_stmts)
  File "C:\Users\Quirk\Documents\RenPy-Competition\renpy\translation\__init__.py", line 166, in take_translates
    raise Exception("Line with id %s appeared twice, at %s:%d and %s:%d." %
Exception: Line with id part_3_murder_memory_f5ff85b5_2 appeared twice, at game/murder.rpy:88 and game/part_3.rpy:68.

Windows-10-10.0.19044 AMD64
Ren'Py 8.0.3.22090809
Us and Them 
Tue Mar 14 23:00:20 2023
